Workbook

Sheet 总览
A1: PIMART 内部库存价格管理
A2: 当前汇率（CNY→JPY） | B2: =系统设置!$C$5 | D2: 网站 | E2: https://pimart-card-production.up.railway.app/?game=pokemon
A3: 更新日期 | B3: 2026-07-07 23:19 | D3: 使用说明：日常在「宝可梦 / 海贼王 / 火影」分页改【库存】+【销售价(JPY)】；「全量库存」自动汇总。汇率和阈值改「系统设置」一次生效。
A5: 核心指标
A6: 库存总金额(JPY) | D6: P0 紧急调价
A7: 在售 SKU | D7: P1 售罄/低毛利
A8: 售罄 SKU | D8: P2 需要补货
A9: 低库存 SKU | D9: 海贼王 SKU 数 | E9: =COUNTIFS(全量库存!$AB$5:$AB$500,"One Piece")
A10: 需要调价 SKU
A11: 汇率风险 SKU
A12: 平均毛利率
A13: 建议补货 SKU
A15: ① 需要调价
A16: 商品名 | B16: 当前售价 | C16: 建议售价 | D16: 毛利率 | E16: 调价建议
A28: ② 低库存
A29: 商品名 | B29: 当前库存 | C29: 预警线 | D29: 库存变化
A41: ③ 汇率风险
A42: 商品名 | B42: 成本CNY | C42: 入货汇率 | D42: 当前汇率 | E42: 汇率差 | F42: 建议
A54: 说明：修改「当前汇率」后全表自动重算；成本价(CNY)/成本汇率为手工录入；#NAME? 已改为带引号工作表引用。

Sheet 系统设置
A1: 系统设置 · 参数中心
A2: 说明：改这里的参数，「总览」「全量库存」全表自动重算；日常只需要在「全量库存」里维护「库存」和「销售价(JPY)」两列。
A4: 汇率设置
A5: 当前汇率（CNY→JPY） | B5: 与「总览」互相联动，改这里两边同步；原数值未改动 | C5: 21.8
A6: 人民币→日元（自动）
A8: 毛利率阈值（原写死在「全量库存」公式里，现集中到这里）
A9: 利润过低阈值 | B9: 毛利率低于此值 → 价格状态标「利润过低」，调价建议「建议涨价」 | C9: 0.1
A10: 目标毛利率 | B10: 毛利率达到此值 → 「利润正常/维持」；也用于反推「建议售价」（售价=成本/(1-目标毛利率)） | C10: 0.2
A12: 风险与库存阈值
A13: 汇率风险阈值 | B13: 汇率差率超过此值 → 标记「汇率风险」 | C13: 0.05
A14: 默认库存预警线 | B14: 参考值；现有商品「全量库存」里已各自设置预警线，此项不覆盖 | C14: 3
A16: 系统信息
A17: 系统名称 | C17: PIMART 内部库存价格管理
A18: 最后更新

Sheet 宝可梦
A1: 宝可梦 · PIMART
A2: 【大纲 1 / 2】点「1」只显示原盒主行（日常改库存/售价）。点「2」或行号旁「+」展开散包/原箱（有规格的新品写到这一层）。新品：先写规格=原盒，再在下方挂散包、原箱两行。
A3: 商品名 | B3: 系列 | C3: 盒型/类型 | D3: 规格 | E3: 销售状态 | F3: 库存 | G3: 销售价(JPY) | H3: 成本价(CNY) | I3: 语言 | J3: 是否预售 | K3: 首页推荐 | L3: 发货天数 | M3: 图片 | N3: 优先级 | O3: 商品类型 | P3: 备注 | Q3: 商品ID | R3: SKU/Slug | S3: 游戏 | T3: 商品链接
A4: 朱・紫 · 扩充包（瘦盒优先 / 新→旧）
A5: 第10弹 · 共逐荣光（瘦盒5张装 / 肥盒20张装）
A6: 补充包 共逐荣光 瘦盒 BOX（简中） | B6: 朱・紫 CSV10c | C6: 瘦盒 | D6: 原盒 | E6: 售罄 | F6: 0 | G6: 6500 | H6: 170 | I6: 简中 | J6: 是 | K6: 是 | L6: 5 | M6: /products/csv10c-slim.png | O6: 扩充包 | P6: 官网/集换社：朱&紫「共逐荣光」同弹分肥瘦。本行=瘦盒（5张装×15包/盒）。配对另一规格见同弹另一行。 | 参考：官网/集换社：同弹肥瘦配对。本行=肥盒（20张装×6包/盒）。 | 朱紫第10弹，2026-07-16发售。含222+张卡牌，全新「训练家的宝可梦」卡牌类型，5张装10元/包，20张装50元/包。 | Q6: c6a43bce026a4cc8a76523 | R6: 共逐荣光-简中-slim-box-简中 | S6: Pokemon | T6: https://pimart-card-production.up.railway.app/products/共逐荣光-box-简中
A7: 补充包 共逐荣光 瘦盒 BOX（简中） | B7: 朱・紫 CSV10c | C7: 瘦盒 | D7: 散包 | E7: 售罄 | H7: 170 | I7: 简中 | J7: 是 | K7: 是 | L7: 5 | M7: /products/csv10c-slim.png | O7: 扩充包 | P7: 官网/集换社：朱&紫「共逐荣光」同弹分肥瘦。本行=瘦盒（5张装×15包/盒）。配对另一规格见同弹另一行。 | 参考：官网/集换社：同弹肥瘦配对。本行=肥盒（20张装×6包/盒）。 | 朱紫第10弹，2026-07-16发售。含222+张卡牌，全新「训练家的宝可梦」卡牌类型，5张装10元/包，20张装50元/包。 | Q7: c6a43bce026a4cc8a76523 | R7: 共逐荣光-简中-slim-box-简中 | S7: Pokemon | T7: https://pimart-card-production.up.railway.app/products/共逐荣光-box-简中
A8: 补充包 共逐荣光 瘦盒 BOX（简中） | B8: 朱・紫 CSV10c | C8: 瘦盒 | D8: 原箱 | E8: 售罄 | H8: 170 | I8: 简中 | J8: 是 | K8: 是 | L8: 5 | M8: /products/csv10c-slim.png | O8: 扩充包 | P8: 官网/集换社：朱&紫「共逐荣光」同弹分肥瘦。本行=瘦盒（5张装×15包/盒）。配对另一规格见同弹另一行。 | 参考：官网/集换社：同弹肥瘦配对。本行=肥盒（20张装×6包/盒）。 | 朱紫第10弹，2026-07-16发售。含222+张卡牌，全新「训练家的宝可梦」卡牌类型，5张装10元/包，20张装50元/包。 | Q8: c6a43bce026a4cc8a76523 | R8: 共逐荣光-简中-slim-box-简中 | S8: Pokemon | T8: https://pimart-card-production.up.railway.app/products/共逐荣光-box-简中
A9: 补充包 共逐荣光 肥盒 BOX（简中） | B9: 朱・紫 CSV10c | C9: 肥盒 | D9: 原盒 | E9: 预售 | F9: 0 | G9: 6500 | H9: 170 | I9: 简中 | J9: 是 | K9: 是 | L9: 5 | M9: /products/csv10c-fat.png | O9: 扩充包 | P9: 官网/集换社：同弹肥瘦配对。本行=肥盒（20张装×6包/盒）。 | 朱紫第10弹，2026-07-16发售。含222+张卡牌，全新「训练家的宝可梦」卡牌类型，5张装10元/包，20张装50元/包。 | Q9: c6a43bce026a4cc8a76523 | R9: 共逐荣光-fat-box-简中 | S9: Pokemon | T9: https://pimart-card-production.up.railway.app/products/共逐荣光-box-简中
A10: 补充包 共逐荣光 肥盒 BOX（简中） | B10: 朱・紫 CSV10c | C10: 肥盒 | D10: 散包 | E10: 预售 | H10: 170 | I10: 简中 | J10: 是 | K10: 是 | L10: 5 | M10: /products/csv10c-fat.png | O10: 扩充包 | P10: 官网/集换社：同弹肥瘦配对。本行=肥盒（20张装×6包/盒）。 | 朱紫第10弹，2026-07-16发售。含222+张卡牌，全新「训练家的宝可梦」卡牌类型，5张装10元/包，20张装50元/包。 | Q10: c6a43bce026a4cc8a76523 | R10: 共逐荣光-fat-box-简中 | S10: Pokemon | T10: https://pimart-card-production.up.railway.app/products/共逐荣光-box-简中
A11: 补充包 共逐荣光 肥盒 BOX（简中） | B11: 朱・紫 CSV10c | C11: 肥盒 | D11: 原箱 | E11: 预售 | H11: 170 | I11: 简中 | J11: 是 | K11: 是 | L11: 5 | M11: /products/csv10c-fat.png | O11: 扩充包 | P11: 官网/集换社：同弹肥瘦配对。本行=肥盒（20张装×6包/盒）。 | 朱紫第10弹，2026-07-16发售。含222+张卡牌，全新「训练家的宝可梦」卡牌类型，5张装10元/包，20张装50元/包。 | Q11: c6a43bce026a4cc8a76523 | R11: 共逐荣光-fat-box-简中 | S11: Pokemon | T11: https://pimart-card-production.up.railway.app/products/共逐荣光-box-简中
A12: 第9弹 · 星彩晶璃（瘦盒5张装 / 肥盒20张装）
A13: 补充包 星彩晶璃 瘦盒 BOX（简中） | B13: 朱・紫 CSV9c | C13: 瘦盒 | D13: 原盒 | E13: 售罄 | F13: 0 | G13: 6200 | H13: 166.34 | I13: 简中 | J13: 否 | K13: 是 | L13: 6 | M13: /products/csv9c-slim.png | O13: 扩充包 | P13: 官网/集换社：朱&紫「星彩晶璃」同弹分肥瘦。本行=瘦盒（5张装×15包/盒）。配对另一规格见同弹另一行。 | 参考：官网/集换社：同弹肥瘦配对。本行=肥盒（20张装×6包/盒）。 | 简中宝可梦 朱・紫 星彩晶璃（Stellar Crown）原盒，2026年4月24日发售。每盒含10包，每包含5张卡牌，必出闪卡。 | Q13: a4af2b9b-e2da-4400-b3cc-3063a0892551 | R13: 星彩晶璃-简中-slim-box-简中 | S13: Pokemon | T13: https://pimart-card-production.up.railway.app/products/%E6%98%9F%E5%BD%A9%E6%99%B6%E7%92%83-box-%E7%AE%80%E4%B8%AD
A14: 补充包 星彩晶璃 瘦盒 BOX（简中） | B14: 朱・紫 CSV9c | C14: 瘦盒 | D14: 散包 | E14: 售罄 | H14: 166.34 | I14: 简中 | J14: 否 | K14: 是 | L14: 6 | M14: /products/csv9c-slim.png | O14: 扩充包 | P14: 官网/集换社：朱&紫「星彩晶璃」同弹分肥瘦。本行=瘦盒（5张装×15包/盒）。配对另一规格见同弹另一行。 | 参考：官网/集换社：同弹肥瘦配对。本行=肥盒（20张装×6包/盒）。 | 简中宝可梦 朱・紫 星彩晶璃（Stellar Crown）原盒，2026年4月24日发售。每盒含10包，每包含5张卡牌，必出闪卡。 | Q14: a4af2b9b-e2da-4400-b3cc-3063a0892551 | R14: 星彩晶璃-简中-slim-box-简中 | S14: Pokemon | T14: https://pimart-card-production.up.railway.app/products/%E6%98%9F%E5%BD%A9%E6%99%B6%E7%92%83-box-%E7%AE%80%E4%B8%AD
A15: 补充包 星彩晶璃 瘦盒 BOX（简中） | B15: 朱・紫 CSV9c | C15: 瘦盒 | D15: 原箱 | E15: 售罄 | H15: 166.34 | I15: 简中 | J15: 否 | K15: 是 | L15: 6 | M15: /products/csv9c-slim.png | O15: 扩充包 | P15: 官网/集换社：朱&紫「星彩晶璃」同弹分肥瘦。本行=瘦盒（5张装×15包/盒）。配对另一规格见同弹另一行。 | 参考：官网/集换社：同弹肥瘦配对。本行=肥盒（20张装×6包/盒）。 | 简中宝可梦 朱・紫 星彩晶璃（Stellar Crown）原盒，2026年4月24日发售。每盒含10包，每包含5张卡牌，必出闪卡。 | Q15: a4af2b9b-e2da-4400-b3cc-3063a0892551 | R15: 星彩晶璃-简中-slim-box-简中 | S15: Pokemon | T15: https://pimart-card-production.up.railway.app/products/%E6%98%9F%E5%BD%A9%E6%99%B6%E7%92%83-box-%E7%AE%80%E4%B8%AD
A16: 补充包 星彩晶璃 肥盒 BOX（简中） | B16: 朱・紫 CSV9c | C16: 肥盒 | D16: 原盒 | E16: 在售 | F16: 20 | G16: 6200 | H16: 166.34 | I16: 简中 | J16: 否 | K16: 是 | L16: 6 | M16: /products/csv9c-fat.png | O16: 扩充包 | P16: 官网/集换社：同弹肥瘦配对。本行=肥盒（20张装×6包/盒）。 | 简中宝可梦 朱・紫 星彩晶璃（Stellar Crown）原盒，2026年4月24日发售。每盒含10包，每包含5张卡牌，必出闪卡。 | Q16: a4af2b9b-e2da-4400-b3cc-3063a0892551 | R16: 星彩晶璃-fat-box-简中 | S16: Pokemon | T16: https://pimart-card-production.up.railway.app/products/%E6%98%9F%E5%BD%A9%E6%99%B6%E7%92%83-box-%E7%AE%80%E4%B8%AD
A17: 补充包 星彩晶璃 肥盒 BOX（简中） | B17: 朱・紫 CSV9c | C17: 肥盒 | D17: 散包 | E17: 在售 | H17: 166.34 | I17: 简中 | J17: 否 | K17: 是 | L17: 6 | M17: /products/csv9c-fat.png | O17: 扩充包 | P17: 官网/集换社：同弹肥瘦配对。本行=肥盒（20张装×6包/盒）。 | 简中宝可梦 朱・紫 星彩晶璃（Stellar Crown）原盒，2026年4月24日发售。每盒含10包，每包含5张卡牌，必出闪卡。 | Q17: a4af2b9b-e2da-4400-b3cc-3063a0892551 | R17: 星彩晶璃-fat-box-简中 | S17: Pokemon | T17: https://pimart-card-production.up.railway.app/products/%E6%98%9F%E5%BD%A9%E6%99%B6%E7%92%83-box-%E7%AE%80%E4%B8%AD
A18: 补充包 星彩晶璃 肥盒 BOX（简中） | B18: 朱・紫 CSV9c | C18: 肥盒 | D18: 原箱 | E18: 在售 | H18: 166.34 | I18: 简中 | J18: 否 | K18: 是 | L18: 6 | M18: /products/csv9c-fat.png | O18: 扩充包 | P18: 官网/集换社：同弹肥瘦配对。本行=肥盒（20张装×6包/盒）。 | 简中宝可梦 朱・紫 星彩晶璃（Stellar Crown）原盒，2026年4月24日发售。每盒含10包，每包含5张卡牌，必出闪卡。 | Q18: a4af2b9b-e2da-4400-b3cc-3063a0892551 | R18: 星彩晶璃-fat-box-简中 | S18: Pokemon | T18: https://pimart-card-production.up.railway.app/products/%E6%98%9F%E5%BD%A9%E6%99%B6%E7%92%83-box-%E7%AE%80%E4%B8%AD
A19: 第8弹 · 璀璨诡幻（瘦盒5张装 / 肥盒20张装）
A20: 补充包 璀璨诡幻 瘦盒 BOX（简中） | B20: 朱・紫 CSV8c | C20: 瘦盒 | D20: 原盒 | E20: 售罄 | F20: 0 | G20: 6000 | H20: 160.98 | I20: 简中 | J20: 否 | K20: 否 | L20: 6 | M20: /products/csv8c-slim.png | O20: 扩充包 | P20: 官网/集换社：同弹肥瘦配对。本行=瘦盒（5张装×15包/盒）。 | 简中宝可梦 朱&紫 璀璨诡幻（CSV8C）原盒，2026年3月13日发售，每盒30包，每包5张。 | Q20: cmqui01q100044odkmmm85re4 | R20: 璀璨诡幻-slim-box-简中 | S20: Pokemon | T20: https://pimart-card-production.up.railway.app/products/%E7%92%80%E7%92%A8%E8%AF%A1%E5%B9%BB-box-%E7%AE%80%E4%B8%AD
A21: 补充包 璀璨诡幻 瘦盒 BOX（简中） | B21: 朱・紫 CSV8c | C21: 瘦盒 | D21: 散包 | E21: 售罄 | H21: 160.98 | I21: 简中 | J21: 否 | K21: 否 | L21: 6 | M21: /products/csv8c-slim.png | O21: 扩充包 | P21: 官网/集换社：同弹肥瘦配对。本行=瘦盒（5张装×15包/盒）。 | 简中宝可梦 朱&紫 璀璨诡幻（CSV8C）原盒，2026年3月13日发售，每盒30包，每包5张。 | Q21: cmqui01q100044odkmmm85re4 | R21: 璀璨诡幻-slim-box-简中 | S21: Pokemon | T21: https://pimart-card-production.up.railway.app/products/%E7%92%80%E7%92%A8%E8%AF%A1%E5%B9%BB-box-%E7%AE%80%E4%B8%AD
A22: 补充包 璀璨诡幻 瘦盒 BOX（简中） | B22: 朱・紫 CSV8c | C22: 瘦盒 | D22: 原箱 | E22: 售罄 | H22: 160.98 | I22: 简中 | J22: 否 | K22: 否 | L22: 6 | M22: /products/csv8c-slim.png | O22: 扩充包 | P22: 官网/集换社：同弹肥瘦配对。本行=瘦盒（5张装×15包/盒）。 | 简中宝可梦 朱&紫 璀璨诡幻（CSV8C）原盒，2026年3月13日发售，每盒30包，每包5张。 | Q22: cmqui01q100044odkmmm85re4 | R22: 璀璨诡幻-slim-box-简中 | S22: Pokemon | T22: https://pimart-card-production.up.railway.app/products/%E7%92%80%E7%92%A8%E8%AF%A1%E5%B9%BB-box-%E7%AE%80%E4%B8%AD
A23: 补充包 璀璨诡幻 肥盒 BOX（简中） | B23: 朱・紫 CSV8c | C23: 肥盒 | D23: 原盒 | E23: 售罄 | F23: 0 | G23: 6000 | H23: 160.98 | I23: 简中 | J23: 否 | K23: 否 | L23: 6 | M23: /products/csv8c-fat.png | O23: 扩充包 | P23: 官网/集换社：朱&紫「璀璨诡幻」同弹分肥瘦。本行=肥盒（20张装×6包/盒）。配对另一规格见同弹另一行。 | 参考：官网/集换社：同弹肥瘦配对。本行=瘦盒（5张装×15包/盒）。 | 简中宝可梦 朱&紫 璀璨诡幻（CSV8C）原盒，2026年3月13日发售，每盒30包，每包5张。 | Q23: cmqui01q100044odkmmm85re4 | R23: 璀璨诡幻-简中-fat-box-简中 | S23: Pokemon | T23: https://pimart-card-production.up.railway.app/products/%E7%92%80%E7%92%A8%E8%AF%A1%E5%B9%BB-box-%E7%AE%80%E4%B8%AD
A24: 补充包 璀璨诡幻 肥盒 BOX（简中） | B24: 朱・紫 CSV8c | C24: 肥盒 | D24: 散包 | E24: 售罄 | H24: 160.98 | I24: 简中 | J24: 否 | K24: 否 | L24: 6 | M24: /products/csv8c-fat.png | O24: 扩充包 | P24: 官网/集换社：朱&紫「璀璨诡幻」同弹分肥瘦。本行=肥盒（20张装×6包/盒）。配对另一规格见同弹另一行。 | 参考：官网/集换社：同弹肥瘦配对。本行=瘦盒（5张装×15包/盒）。 | 简中宝可梦 朱&紫 璀璨诡幻（CSV8C）原盒，2026年3月13日发售，每盒30包，每包5张。 | Q24: cmqui01q100044odkmmm85re4 | R24: 璀璨诡幻-简中-fat-box-简中 | S24: Pokemon | T24: https://pimart-card-production.up.railway.app/products/%E7%92%80%E7%92%A8%E8%AF%A1%E5%B9%BB-box-%E7%AE%80%E4%B8%AD
A25: 补充包 璀璨诡幻 肥盒 BOX（简中） | B25: 朱・紫 CSV8c | C25: 肥盒 | D25: 原箱 | E25: 售罄 | H25: 160.98 | I25: 简中 | J25: 否 | K25: 否 | L25: 6 | M25: /products/csv8c-fat.png | O25: 扩充包 | P25: 官网/集换社：朱&紫「璀璨诡幻」同弹分肥瘦。本行=肥盒（20张装×6包/盒）。配对另一规格见同弹另一行。 | 参考：官网/集换社：同弹肥瘦配对。本行=瘦盒（5张装×15包/盒）。 | 简中宝可梦 朱&紫 璀璨诡幻（CSV8C）原盒，2026年3月13日发售，每盒30包，每包5张。 | Q25: cmqui01q100044odkmmm85re4 | R25: 璀璨诡幻-简中-fat-box-简中 | S25: Pokemon | T25: https://pimart-card-production.up.railway.app/products/%E7%92%80%E7%92%A8%E8%AF%A1%E5%B9%BB-box-%E7%AE%80%E4%B8%AD
A26: 第7弹 · 利刃猛醒（瘦盒5张装 / 肥盒20张装）
A27: 补充包 利刃猛醒 瘦盒 BOX（简中） | B27: 朱・紫 CSV7c | C27: 瘦盒 | D27: 原盒 | E27: 售罄 | F27: 0 | G27: 5800 | H27: 155.61 | I27: 简中 | J27: 否 | K27: 否 | L27: 6 | M27: /products/csv7c-slim.png | O27: 扩充包 | P27: 官网/集换社：朱&紫「利刃猛醒」同弹分肥瘦。本行=瘦盒（5张装×15包/盒）。配对另一规格见同弹另一行。 | 参考：官网/集换社：同弹肥瘦配对。本行=肥盒（20张装×6包/盒）。 | 简中宝可梦 朱・紫 剑刃觉醒（Blade Awakening）原盒，现货发售。 | Q27: 470d321e-88ab-4e61-bcb9-94fa1ff06d18 | R27: 剑刃觉醒-简中-slim-box-简中 | S27: Pokemon | T27: https://pimart-card-production.up.railway.app/products/%E5%89%91%E5%88%83%E8%A7%89%E9%86%92-box-%E7%AE%80%E4%B8%AD
A28: 补充包 利刃猛醒 瘦盒 BOX（简中） | B28: 朱・紫 CSV7c | C28: 瘦盒 | D28: 散包 | E28: 售罄 | H28: 155.61 | I28: 简中 | J28: 否 | K28: 否 | L28: 6 | M28: /products/csv7c-slim.png | O28: 扩充包 | P28: 官网/集换社：朱&紫「利刃猛醒」同弹分肥瘦。本行=瘦盒（5张装×15包/盒）。配对另一规格见同弹另一行。 | 参考：官网/集换社：同弹肥瘦配对。本行=肥盒（20张装×6包/盒）。 | 简中宝可梦 朱・紫 剑刃觉醒（Blade Awakening）原盒，现货发售。 | Q28: 470d321e-88ab-4e61-bcb9-94fa1ff06d18 | R28: 剑刃觉醒-简中-slim-box-简中 | S28: Pokemon | T28: https://pimart-card-production.up.railway.app/products/%E5%89%91%E5%88%83%E8%A7%89%E9%86%92-box-%E7%AE%80%E4%B8%AD
A29: 补充包 利刃猛醒 瘦盒 BOX（简中） | B29: 朱・紫 CSV7c | C29: 瘦盒 | D29: 原箱 | E29: 售罄 | H29: 155.61 | I29: 简中 | J29: 否 | K29: 否 | L29: 6 | M29: /products/csv7c-slim.png | O29: 扩充包 | P29: 官网/集换社：朱&紫「利刃猛醒」同弹分肥瘦。本行=瘦盒（5张装×15包/盒）。配对另一规格见同弹另一行。 | 参考：官网/集换社：同弹肥瘦配对。本行=肥盒（20张装×6包/盒）。 | 简中宝可梦 朱・紫 剑刃觉醒（Blade Awakening）原盒，现货发售。 | Q29: 470d321e-88ab-4e61-bcb9-94fa1ff06d18 | R29: 剑刃觉醒-简中-slim-box-简中 | S29: Pokemon | T29: https://pimart-card-production.up.railway.app/products/%E5%89%91%E5%88%83%E8%A7%89%E9%86%92-box-%E7%AE%80%E4%B8%AD
A30: 补充包 利刃猛醒 肥盒 BOX（简中） | B30: 朱・紫 CSV7c | C30: 肥盒 | D30: 原盒 | E30: 在售 | F30: 18 | G30: 5800 | H30: 155.61 | I30: 简中 | J30: 否 | K30: 否 | L30: 6 | M30: /products/csv7c-fat.png | O30: 扩充包 | P30: 官网/集换社：同弹肥瘦配对。本行=肥盒（20张装×6包/盒）。 | 简中宝可梦 朱・紫 剑刃觉醒（Blade Awakening）原盒，现货发售。 | Q30: 470d321e-88ab-4e61-bcb9-94fa1ff06d18 | R30: 剑刃觉醒-fat-box-简中 | S30: Pokemon | T30: https://pimart-card-production.up.railway.app/products/%E5%89%91%E5%88%83%E8%A7%89%E9%86%92-box-%E7%AE%80%E4%B8%AD
A31: 补充包 利刃猛醒 肥盒 BOX（简中） | B31: 朱・紫 CSV7c | C31: 肥盒 | D31: 散包 | E31: 在售 | H31: 155.61 | I31: 简中 | J31: 否 | K31: 否 | L31: 6 | M31: /products/csv7c-fat.png | O31: 扩充包 | P31: 官网/集换社：同弹肥瘦配对。本行=肥盒（20张装×6包/盒）。 | 简中宝可梦 朱・紫 剑刃觉醒（Blade Awakening）原盒，现货发售。 | Q31: 470d321e-88ab-4e61-bcb9-94fa1ff06d18 | R31: 剑刃觉醒-fat-box-简中 | S31: Pokemon | T31: https://pimart-card-production.up.railway.app/products/%E5%89%91%E5%88%83%E8%A7%89%E9%86%92-box-%E7%AE%80%E4%B8%AD
A32: 补充包 利刃猛醒 肥盒 BOX（简中） | B32: 朱・紫 CSV7c | C32: 肥盒 | D32: 原箱 | E32: 在售 | H32: 155.61 | I32: 简中 | J32: 否 | K32: 否 | L32: 6 | M32: /products/csv7c-fat.png | O32: 扩充包 | P32: 官网/集换社：同弹肥瘦配对。本行=肥盒（20张装×6包/盒）。 | 简中宝可梦 朱・紫 剑刃觉醒（Blade Awakening）原盒，现货发售。 | Q32: 470d321e-88ab-4e61-bcb9-94fa1ff06d18 | R32: 剑刃觉醒-fat-box-简中 | S32: Pokemon | T32: https://pimart-card-production.up.railway.app/products/%E5%89%91%E5%88%83%E8%A7%89%E9%86%92-box-%E7%AE%80%E4%B8%AD
A33: 第6弹 · 真实玄虚（瘦盒5张装 / 肥盒20张装）
A34: 补充包 真实玄虚 瘦盒 BOX（简中） | B34: 朱・紫 CSV6c | C34: 瘦盒 | D34: 原盒 | E34: 售罄 | F34: 0 | G34: 5600 | H34: 150.24 | I34: 简中 | J34: 否 | K34: 否 | L34: 6 | M34: /products/csv6c-slim.png | O34: 扩充包 | P34: 官网/集换社：同弹肥瘦配对。本行=瘦盒（5张装×15包/盒）。 | 简中宝可梦 朱&紫 真实玄虚（CSV6C）原盒，2025年11月7日发售，每盒30包，每包5张。 | Q34: cmqui01pw00034odkfh4woe8g | R34: 真实玄虚-slim-box-简中 | S34: Pokemon | T34: https://pimart-card-production.up.railway.app/products/%E7%9C%9F%E5%AE%9E%E7%8E%84%E8%99%9A-box-%E7%AE%80%E4%B8%AD
A35: 补充包 真实玄虚 瘦盒 BOX（简中） | B35: 朱・紫 CSV6c | C35: 瘦盒 | D35: 散包 | E35: 售罄 | H35: 150.24 | I35: 简中 | J35: 否 | K35: 否 | L35: 6 | M35: /products/csv6c-slim.png | O35: 扩充包 | P35: 官网/集换社：同弹肥瘦配对。本行=瘦盒（5张装×15包/盒）。 | 简中宝可梦 朱&紫 真实玄虚（CSV6C）原盒，2025年11月7日发售，每盒30包，每包5张。 | Q35: cmqui01pw00034odkfh4woe8g | R35: 真实玄虚-slim-box-简中 | S35: Pokemon | T35: https://pimart-card-production.up.railway.app/products/%E7%9C%9F%E5%AE%9E%E7%8E%84%E8%99%9A-box-%E7%AE%80%E4%B8%AD
A36: 补充包 真实玄虚 瘦盒 BOX（简中） | B36: 朱・紫 CSV6c | C36: 瘦盒 | D36: 原箱 | E36: 售罄 | H36: 150.24 | I36: 简中 | J36: 否 | K36: 否 | L36: 6 | M36: /products/csv6c-slim.png | O36: 扩充包 | P36: 官网/集换社：同弹肥瘦配对。本行=瘦盒（5张装×15包/盒）。 | 简中宝可梦 朱&紫 真实玄虚（CSV6C）原盒，2025年11月7日发售，每盒30包，每包5张。 | Q36: cmqui01pw00034odkfh4woe8g | R36: 真实玄虚-slim-box-简中 | S36: Pokemon | T36: https://pimart-card-production.up.railway.app/products/%E7%9C%9F%E5%AE%9E%E7%8E%84%E8%99%9A-box-%E7%AE%80%E4%B8%AD
A37: 补充包 真实玄虚 肥盒 BOX（简中） | B37: 朱・紫 CSV6c | C37: 肥盒 | D37: 原盒 | E37: 售罄 | F37: 0 | G37: 5600 | H37: 150.24 | I37: 简中 | J37: 否 | K37: 否 | L37: 6 | M37: /products/csv6c-fat.png | O37: 扩充包 | P37: 官网/集换社：朱&紫「真实玄虚」同弹分肥瘦。本行=肥盒（20张装×6包/盒）。配对另一规格见同弹另一行。 | 参考：官网/集换社：同弹肥瘦配对。本行=瘦盒（5张装×15包/盒）。 | 简中宝可梦 朱&紫 真实玄虚（CSV6C）原盒，2025年11月7日发售，每盒30包，每包5张。 | Q37: cmqui01pw00034odkfh4woe8g | R37: 真实玄虚-简中-fat-box-简中 | S37: Pokemon | T37: https://pimart-card-production.up.railway.app/products/%E7%9C%9F%E5%AE%9E%E7%8E%84%E8%99%9A-box-%E7%AE%80%E4%B8%AD
A38: 补充包 真实玄虚 肥盒 BOX（简中） | B38: 朱・紫 CSV6c | C38: 肥盒 | D38: 散包 | E38: 售罄 | H38: 150.24 | I38: 简中 | J38: 否 | K38: 否 | L38: 6 | M38: /products/csv6c-fat.png | O38: 扩充包 | P38: 官网/集换社：朱&紫「真实玄虚」同弹分肥瘦。本行=肥盒（20张装×6包/盒）。配对另一规格见同弹另一行。 | 参考：官网/集换社：同弹肥瘦配对。本行=瘦盒（5张装×15包/盒）。 | 简中宝可梦 朱&紫 真实玄虚（CSV6C）原盒，2025年11月7日发售，每盒30包，每包5张。 | Q38: cmqui01pw00034odkfh4woe8g | R38: 真实玄虚-简中-fat-box-简中 | S38: Pokemon | T38: https://pimart-card-production.up.railway.app/products/%E7%9C%9F%E5%AE%9E%E7%8E%84%E8%99%9A-box-%E7%AE%80%E4%B8%AD
A39: 补充包 真实玄虚 肥盒 BOX（简中） | B39: 朱・紫 CSV6c | C39: 肥盒 | D39: 原箱 | E39: 售罄 | H39: 150.24 | I39: 简中 | J39: 否 | K39: 否 | L39: 6 | M39: /products/csv6c-fat.png | O39: 扩充包 | P39: 官网/集换社：朱&紫「真实玄虚」同弹分肥瘦。本行=肥盒（20张装×6包/盒）。配对另一规格见同弹另一行。 | 参考：官网/集换社：同弹肥瘦配对。本行=瘦盒（5张装×15包/盒）。 | 简中宝可梦 朱&紫 真实玄虚（CSV6C）原盒，2025年11月7日发售，每盒30包，每包5张。 | Q39: cmqui01pw00034odkfh4woe8g | R39: 真实玄虚-简中-fat-box-简中 | S39: Pokemon | T39: https://pimart-card-production.up.railway.app/products/%E7%9C%9F%E5%AE%9E%E7%8E%84%E8%99%9A-box-%E7%AE%80%E4%B8%AD
A40: 第5弹 · 黑晶炽诚（瘦盒5张装 / 肥盒20张装）
...

Sheet 海贼王
A1: 海贼王 · PIMART
A2: 【大纲 1 / 2】点「1」只显示原盒主行（日常改库存/售价）。点「2」或行号旁「+」展开散包/原箱（有规格的新品写到这一层）。新品：先写规格=原盒，再在下方挂散包、原箱两行。
A4: 商品名 | B4: 系列 | C4: 盒型/类型 | D4: 规格 | E4: 销售状态 | F4: 库存 | G4: 销售价(JPY) | H4: 成本价(CNY) | I4: 语言 | J4: 网站状态 | K4: 是否预售 | L4: 首页推荐 | M4: 发售日 | N4: 发货天数 | O4: 图片 | P4: 优先级 | Q4: 商品类型 | R4: 备注 | S4: 商品ID | T4: SKU/Slug | U4: 游戏 | V4: 商品链接
A5: OPC 主弹补充包（新→旧）
A6: OPC-16 决战之时 原盒（简中） | B6: OPC-16 | C6: 原盒 | D6: 原盒 | E6: 售罄 | F6: 0 | G6: 5500 | I6: 简中 | J6: 未上架 | K6: 否 | M6: 2026-05-30T00:00:00 | O6: /products/onepiece-official/opc-16-pack.png | Q6: 扩充包 | R6: 官方 onepiece-cardgame.cn 已发售（主线编号弹，本店缺失（最新一弹）），本店未查到对应商品页，暂未上架。价格/库存/成本待你核实补录。 | 官方：决战之时。对照站内DB/集换社补库存价。 | U6: 海贼王
A7: OPC-16 决战之时 散包（简中） | B7: OPC-16 | C7: 原盒 | D7: 散包 | E7: 售罄 | F7: 0 | G7: 200 | I7: 简中 | J7: 未上架 | K7: 否 | M7: 2026-05-30T00:00:00 | O7: /products/onepiece-official/opc-16-pack.png | Q7: 扩充包 | R7: 官方 onepiece-cardgame.cn 已发售（主线编号弹，本店缺失（最新一弹）），本店未查到对应商品页，暂未上架。价格/库存/成本待你核实补录。 | 官方：决战之时。对照站内DB/集换社补库存价。 | U7: 海贼王
A8: OPC-16 决战之时 原箱（简中） | B8: OPC-16 | C8: 原盒 | D8: 原箱 | E8: 售罄 | F8: 0 | G8: 66000 | I8: 简中 | J8: 未上架 | K8: 否 | M8: 2026-05-30T00:00:00 | O8: /products/onepiece-official/opc-16-pack.png | Q8: 扩充包 | R8: 官方 onepiece-cardgame.cn 已发售（主线编号弹，本店缺失（最新一弹）），本店未查到对应商品页，暂未上架。价格/库存/成本待你核实补录。 | 官方：决战之时。对照站内DB/集换社补库存价。 | U8: 海贼王
A9: OPC-15 神之岛的冒险 原盒（简中） | B9: OPC-15 | C9: 原盒 | D9: 原盒 | E9: 售罄 | F9: 0 | G9: 5500 | I9: 简中 | J9: 上架 | K9: 否 | M9: 2026-03-14T00:00:00 | O9: /products/onepiece-official/opc-15-pack.png | Q9: 扩充包 | R9: 成本价/成本汇率待补录（Obsidian 暂无海贼王产品笔记）。 官方发售日 2026-03-14（来自 onepiece-cardgame.cn 官方数据）。 | 官方：神之岛的冒险。对照站内DB/集换社补库存价。 | T9: opc-15-adventure-gods-island-box | U9: One Piece | V9: https://pimart-card-production.up.railway.app/products/opc-15-adventure-gods-island-box
A10: OPC-15 神之岛的冒险 散包（简中） | B10: OPC-15 | C10: 原盒 | D10: 散包 | E10: 售罄 | F10: 0 | G10: 200 | I10: 简中 | J10: 上架 | K10: 否 | M10: 2026-03-14T00:00:00 | O10: /products/onepiece-official/opc-15-pack.png | Q10: 扩充包 | R10: 成本价/成本汇率待补录（Obsidian 暂无海贼王产品笔记）。 官方发售日 2026-03-14（来自 onepiece-cardgame.cn 官方数据）。 | 官方：神之岛的冒险。对照站内DB/集换社补库存价。 | T10: opc-15-adventure-gods-island-box | U10: One Piece | V10: https://pimart-card-production.up.railway.app/products/opc-15-adventure-gods-island-box
A11: OPC-15 神之岛的冒险 原箱（简中） | B11: OPC-15 | C11: 原盒 | D11: 原箱 | E11: 售罄 | F11: 0 | G11: 66000 | I11: 简中 | J11: 上架 | K11: 否 | M11: 2026-03-14T00:00:00 | O11: /products/onepiece-official/opc-15-pack.png | Q11: 扩充包 | R11: 成本价/成本汇率待补录（Obsidian 暂无海贼王产品笔记）。 官方发售日 2026-03-14（来自 onepiece-cardgame.cn 官方数据）。 | 官方：神之岛的冒险。对照站内DB/集换社补库存价。 | T11: opc-15-adventure-gods-island-box | U11: One Piece | V11: https://pimart-card-production.up.railway.app/products/opc-15-adventure-gods-island-box
A12: OPC-14 苍海七杰 原盒（简中） | B12: OPC-14 | C12: 原盒 | D12: 原盒 | E12: 售罄 | F12: 0 | G12: 5500 | I12: 简中 | J12: 上架 | K12: 否 | M12: 2025-12-04T00:00:00 | O12: /products/onepiece-official/opc-14-pack.png | Q12: 扩充包 | R12: 成本价/成本汇率待补录（Obsidian 暂无海贼王产品笔记）。 官方发售日 2025-12-04（来自 onepiece-cardgame.cn 官方数据）。 | 官方：苍海七杰。对照站内DB/集换社补库存价。 | T12: opc-14-cyan-sea-seven-box | U12: One Piece | V12: https://pimart-card-production.up.railway.app/products/opc-14-cyan-sea-seven-box
A13: OPC-14 苍海七杰 散包（简中） | B13: OPC-14 | C13: 原盒 | D13: 散包 | E13: 售罄 | F13: 0 | G13: 200 | I13: 简中 | J13: 上架 | K13: 否 | M13: 2025-12-04T00:00:00 | O13: /products/onepiece-official/opc-14-pack.png | Q13: 扩充包 | R13: 成本价/成本汇率待补录（Obsidian 暂无海贼王产品笔记）。 官方发售日 2025-12-04（来自 onepiece-cardgame.cn 官方数据）。 | 官方：苍海七杰。对照站内DB/集换社补库存价。 | T13: opc-14-cyan-sea-seven-box | U13: One Piece | V13: https://pimart-card-production.up.railway.app/products/opc-14-cyan-sea-seven-box
A14: OPC-14 苍海七杰 原箱（简中） | B14: OPC-14 | C14: 原盒 | D14: 原箱 | E14: 售罄 | F14: 0 | G14: 66000 | I14: 简中 | J14: 上架 | K14: 否 | M14: 2025-12-04T00:00:00 | O14: /products/onepiece-official/opc-14-pack.png | Q14: 扩充包 | R14: 成本价/成本汇率待补录（Obsidian 暂无海贼王产品笔记）。 官方发售日 2025-12-04（来自 onepiece-cardgame.cn 官方数据）。 | 官方：苍海七杰。对照站内DB/集换社补库存价。 | T14: opc-14-cyan-sea-seven-box | U14: One Piece | V14: https://pimart-card-production.up.railway.app/products/opc-14-cyan-sea-seven-box
A15: OPC-13 继承的意志 原盒（简中） | B15: OPC-13 | C15: 原盒 | D15: 原盒 | E15: 售罄 | F15: 0 | G15: 5500 | I15: 简中 | J15: 未上架 | K15: 否 | M15: 2025-09-16T00:00:00 | O15: /products/onepiece-official/opc-13-pack.png | Q15: 扩充包 | R15: 官方中文名：继承的意志。简中定价/库存待对照集换社与官网补录。 | U15: 海贼王
A16: OPC-13 继承的意志 散包（简中） | B16: OPC-13 | C16: 原盒 | D16: 散包 | E16: 售罄 | F16: 0 | G16: 200 | I16: 简中 | J16: 未上架 | K16: 否 | M16: 2025-09-16T00:00:00 | O16: /products/onepiece-official/opc-13-pack.png | Q16: 扩充包 | R16: 官方 onepiece-cardgame.cn 已发售（主线编号弹，本店缺失），本店未查到对应商品页，暂未上架。价格/库存/成本待你核实补录。 | 官方：继承的意志。对照站内DB/集换社补库存价。 | U16: 海贼王
A17: OPC-13 继承的意志 原箱（简中） | B17: OPC-13 | C17: 原盒 | D17: 原箱 | E17: 售罄 | F17: 0 | G17: 66000 | I17: 简中 | J17: 未上架 | K17: 否 | M17: 2025-09-16T00:00:00 | O17: /products/onepiece-official/opc-13-pack.png | Q17: 扩充包 | R17: 官方 onepiece-cardgame.cn 已发售（主线编号弹，本店缺失），本店未查到对应商品页，暂未上架。价格/库存/成本待你核实补录。 | 官方：继承的意志。对照站内DB/集换社补库存价。 | U17: 海贼王
A18: OPC-12 师徒之绊 原盒（简中） | B18: OPC-12 | C18: 原盒 | D18: 原盒 | E18: 售罄 | F18: 0 | G18: 5500 | I18: 简中 | J18: 未上架 | K18: 否 | M18: 2025-07-17T00:00:00 | O18: /products/onepiece-official/opc-12-pack.png | Q18: 扩充包 | R18: 官方中文名：师徒之绊。简中定价/库存待对照集换社与官网补录。 | U18: 海贼王
A19: OPC-12 师徒之绊 散包（简中） | B19: OPC-12 | C19: 原盒 | D19: 散包 | E19: 售罄 | F19: 0 | G19: 200 | I19: 简中 | J19: 未上架 | K19: 否 | M19: 2025-07-17T00:00:00 | O19: /products/onepiece-official/opc-12-pack.png | Q19: 扩充包 | R19: 官方 onepiece-cardgame.cn 已发售（主线编号弹，本店缺失），本店未查到对应商品页，暂未上架。价格/库存/成本待你核实补录。 | 官方：师徒之绊。对照站内DB/集换社补库存价。 | U19: 海贼王
A20: OPC-12 师徒之绊 原箱（简中） | B20: OPC-12 | C20: 原盒 | D20: 原箱 | E20: 售罄 | F20: 0 | G20: 66000 | I20: 简中 | J20: 未上架 | K20: 否 | M20: 2025-07-17T00:00:00 | O20: /products/onepiece-official/opc-12-pack.png | Q20: 扩充包 | R20: 官方 onepiece-cardgame.cn 已发售（主线编号弹，本店缺失），本店未查到对应商品页，暂未上架。价格/库存/成本待你核实补录。 | 官方：师徒之绊。对照站内DB/集换社补库存价。 | U20: 海贼王
A21: OPC-11 神速之拳 原盒（简中） | B21: OPC-11 | C21: 原盒 | D21: 原盒 | E21: 在售 | F21: 100 | G21: 5500 | I21: 简中 | J21: 上架 | K21: 否 | M21: 2025-04-09T00:00:00 | O21: /products/onepiece-official/opc-11-pack.png | Q21: 扩充包 | R21: 成本价/成本汇率待补录（Obsidian 暂无海贼王产品笔记）。网站显示「有货」但未展示精确库存数字，请手动核实后填入。 官方发售日 2025-04-09（来自 onepiece-cardgame.cn 官方数据）。 | 官方：神速之拳。对照站内DB/集换社补库存价。 | T21: opc-11-divine-speed-box | U21: One Piece | V21: https://pimart-card-production.up.railway.app/products/opc-11-divine-speed-box
A22: OPC-11 神速之拳 散包（简中） | B22: OPC-11 | C22: 原盒 | D22: 散包 | E22: 在售 | F22: 400 | G22: 200 | I22: 简中 | J22: 上架 | K22: 否 | M22: 2025-04-09T00:00:00 | O22: /products/onepiece-official/opc-11-pack.png | Q22: 扩充包 | R22: 成本价/成本汇率待补录（Obsidian 暂无海贼王产品笔记）。网站显示「有货」但未展示精确库存数字，请手动核实后填入。 官方发售日 2025-04-09（来自 onepiece-cardgame.cn 官方数据）。 | 官方：神速之拳。对照站内DB/集换社补库存价。 | T22: opc-11-divine-speed-box | U22: One Piece | V22: https://pimart-card-production.up.railway.app/products/opc-11-divine-speed-box
A23: OPC-11 神速之拳 原箱（简中） | B23: OPC-11 | C23: 原盒 | D23: 原箱 | E23: 在售 | F23: 8 | G23: 66000 | I23: 简中 | J23: 上架 | K23: 否 | M23: 2025-04-09T00:00:00 | O23: /products/onepiece-official/opc-11-pack.png | Q23: 扩充包 | R23: 成本价/成本汇率待补录（Obsidian 暂无海贼王产品笔记）。网站显示「有货」但未展示精确库存数字，请手动核实后填入。 官方发售日 2025-04-09（来自 onepiece-cardgame.cn 官方数据）。 | 官方：神速之拳。对照站内DB/集换社补库存价。 | T23: opc-11-divine-speed-box | U23: One Piece | V23: https://pimart-card-production.up.railway.app/products/opc-11-divine-speed-box
A24: OPC-10 王之血脉 原盒（简中） | B24: OPC-10 | C24: 原盒 | D24: 原盒 | E24: 在售 | F24: 100 | G24: 5500 | I24: 简中 | J24: 上架 | K24: 否 | M24: 2025-01-16T00:00:00 | O24: /products/onepiece-official/opc-10-pack.png | Q24: 扩充包 | R24: 成本价/成本汇率待补录（Obsidian 暂无海贼王产品笔记）。网站显示「有货」但未展示精确库存数字，请手动核实后填入。 官方发售日 2025-01-16（来自 onepiece-cardgame.cn 官方数据）。 | 官方：王之血脉。对照站内DB/集换社补库存价。 | T24: opc-10-royal-blood-box | U24: One Piece | V24: https://pimart-card-production.up.railway.app/products/opc-10-royal-blood-box
A25: OPC-10 王之血脉 散包（简中） | B25: OPC-10 | C25: 原盒 | D25: 散包 | E25: 在售 | F25: 400 | G25: 200 | I25: 简中 | J25: 上架 | K25: 否 | M25: 2025-01-16T00:00:00 | O25: /products/onepiece-official/opc-10-pack.png | Q25: 扩充包 | R25: 成本价/成本汇率待补录（Obsidian 暂无海贼王产品笔记）。网站显示「有货」但未展示精确库存数字，请手动核实后填入。 官方发售日 2025-01-16（来自 onepiece-cardgame.cn 官方数据）。 | 官方：王之血脉。对照站内DB/集换社补库存价。 | T25: opc-10-royal-blood-box | U25: One Piece | V25: https://pimart-card-production.up.railway.app/products/opc-10-royal-blood-box
A26: OPC-10 王之血脉 原箱（简中） | B26: OPC-10 | C26: 原盒 | D26: 原箱 | E26: 在售 | F26: 8 | G26: 66000 | I26: 简中 | J26: 上架 | K26: 否 | M26: 2025-01-16T00:00:00 | O26: /products/onepiece-official/opc-10-pack.png | Q26: 扩充包 | R26: 成本价/成本汇率待补录（Obsidian 暂无海贼王产品笔记）。网站显示「有货」但未展示精确库存数字，请手动核实后填入。 官方发售日 2025-01-16（来自 onepiece-cardgame.cn 官方数据）。 | 官方：王之血脉。对照站内DB/集换社补库存价。 | T26: opc-10-royal-blood-box | U26: One Piece | V26: https://pimart-card-production.up.railway.app/products/opc-10-royal-blood-box
A27: OPC-09 新帝降临 原盒（简中） | B27: OPC-09 | C27: 原盒 | D27: 原盒 | E27: 在售 | F27: 100 | G27: 5500 | I27: 简中 | J27: 上架 | K27: 否 | M27: 2024-10-18T00:00:00 | O27: /products/onepiece-official/opc-09-pack.png | Q27: 扩充包 | R27: 成本价/成本汇率待补录（Obsidian 暂无海贼王产品笔记）。网站显示「有货」但未展示精确库存数字，请手动核实后填入。 官方发售日 2024-10-18（来自 onepiece-cardgame.cn 官方数据）。 | 官方：新帝降临。对照站内DB/集换社补库存价。 | T27: opc-09-emperors-new-world-box | U27: One Piece | V27: https://pimart-card-production.up.railway.app/products/opc-09-emperors-new-world-box
A28: OPC-09 新帝降临 散包（简中） | B28: OPC-09 | C28: 原盒 | D28: 散包 | E28: 在售 | F28: 400 | G28: 200 | I28: 简中 | J28: 上架 | K28: 否 | M28: 2024-10-18T00:00:00 | O28: /products/onepiece-official/opc-09-pack.png | Q28: 扩充包 | R28: 成本价/成本汇率待补录（Obsidian 暂无海贼王产品笔记）。网站显示「有货」但未展示精确库存数字，请手动核实后填入。 官方发售日 2024-10-18（来自 onepiece-cardgame.cn 官方数据）。 | 官方：新帝降临。对照站内DB/集换社补库存价。 | T28: opc-09-emperors-new-world-box | U28: One Piece | V28: https://pimart-card-production.up.railway.app/products/opc-09-emperors-new-world-box
A29: OPC-09 新帝降临 原箱（简中） | B29: OPC-09 | C29: 原盒 | D29: 原箱 | E29: 在售 | F29: 8 | G29: 66000 | I29: 简中 | J29: 上架 | K29: 否 | M29: 2024-10-18T00:00:00 | O29: /products/onepiece-official/opc-09-pack.png | Q29: 扩充包 | R29: 成本价/成本汇率待补录（Obsidian 暂无海贼王产品笔记）。网站显示「有货」但未展示精确库存数字，请手动核实后填入。 官方发售日 2024-10-18（来自 onepiece-cardgame.cn 官方数据）。 | 官方：新帝降临。对照站内DB/集换社补库存价。 | T29: opc-09-emperors-new-world-box | U29: One Piece | V29: https://pimart-card-production.up.railway.app/products/opc-09-emperors-new-world-box
A30: OPC-08 双子传说 原盒（简中） | B30: OPC-08 | C30: 原盒 | D30: 原盒 | E30: 在售 | F30: 100 | G30: 5800 | I30: 简中 | J30: 上架 | K30: 否 | M30: 2024-07-15T00:00:00 | O30: /products/onepiece-official/opc-08-pack.png | Q30: 扩充包 | R30: 成本价/成本汇率待补录（Obsidian 暂无海贼王产品笔记）。网站显示「有货」但未展示精确库存数字，请手动核实后填入。 官方发售日 2024-07-15；官方接口名称为「传说的强者」，与本店商品名不完全一致，请核实是否为同一弹。 | 官方：双子传说。对照站内DB/集换社补库存价。 | T30: opc-08-two-legends-box | U30: One Piece | V30: https://pimart-card-production.up.railway.app/products/opc-08-two-legends-box
A31: OPC-08 双子传说 散包（简中） | B31: OPC-08 | C31: 原盒 | D31: 散包 | E31: 在售 | F31: 400 | G31: 200 | I31: 简中 | J31: 上架 | K31: 否 | M31: 2024-07-15T00:00:00 | O31: /products/onepiece-official/opc-08-pack.png | Q31: 扩充包 | R31: 成本价/成本汇率待补录（Obsidian 暂无海贼王产品笔记）。网站显示「有货」但未展示精确库存数字，请手动核实后填入。 官方发售日 2024-07-15；官方接口名称为「传说的强者」，与本店商品名不完全一致，请核实是否为同一弹。 | 官方：双子传说。对照站内DB/集换社补库存价。 | T31: opc-08-two-legends-box | U31: One Piece | V31: https://pimart-card-production.up.railway.app/products/opc-08-two-legends-box
A32: OPC-08 双子传说 原箱（简中） | B32: OPC-08 | C32: 原盒 | D32: 原箱 | E32: 在售 | F32: 100 | G32: 69600 | I32: 简中 | J32: 上架 | K32: 否 | M32: 2024-07-15T00:00:00 | O32: /products/onepiece-official/opc-08-pack.png | Q32: 扩充包 | R32: 成本价/成本汇率待补录（Obsidian 暂无海贼王产品笔记）。网站显示「有货」但未展示精确库存数字，请手动核实后填入。 官方发售日 2024-07-15；官方接口名称为「传说的强者」，与本店商品名不完全一致，请核实是否为同一弹。 | 官方：双子传说。对照站内DB/集换社补库存价。 | T32: opc-08-two-legends-box | U32: One Piece | V32: https://pimart-card-production.up.railway.app/products/opc-08-two-legends-box
... A53: OPC-01 冒险的黎明 原箱（简中） | B53: OPC-01 | C53: 原盒 | D53: 原箱 | E53: 售罄 | F53: 0 | G53: 117600 | I53: 简中 | J53: 上架 | K53: 否 | M53: 2022-11-18T00:00:00 | O53: /products/onepiece-official/opc-01-pack.png | Q53: 扩充包 | R53: 成本价/成本汇率待补录（Obsidian 暂无海贼王产品笔记）。 官方发售日 2022-11-18（来自 onepiece-cardgame.cn 官方数据）。 | 官方：冒险的黎明。对照站内DB/集换社补库存价。 | T53: opc-01-romance-dawn-box | U53: One Piece | V53: https://pimart-card-production.up.railway.app/products/opc-01-romance-dawn-box
A55: EB 特别补充包 | O55: /products/placeholder.svg
A56: EBC-04 艾格赫德危机 原盒（简中） | B56: EBC-04 | C56: 原盒 | D56: 原盒 | E56: 售罄 | F56: 0 | I56: 简中 | J56: 未上架 | K56: 否 | M56: 2026-02-02T00:00:00 | O56: /products/onepiece-official/ebc-04-pack.png | Q56: 扩充包 | R56: 特别补充包 艾格赫德危机。简中定价待官方/集换社。 | U56: 海贼王
A57: EBC-04 艾格赫德危机 散包（简中） | B57: EBC-04 | C57: 原盒 | D57: 散包 | E57: 在售 | F57: 0 | I57: 简中 | J57: 未上架 | K57: 否 | M57: 2026-02-02T00:00:00 | O57: /products/onepiece-official/ebc-04-pack.png | Q57: 扩充包 | R57: 官方 onepiece-cardgame.cn 已发售（特别篇），本店未查到对应商品页，暂未上架。价格/库存/成本待你核实补录。 | U57: 海贼王
A58: EBC-04 艾格赫德危机 原箱（简中） | B58: EBC-04 | C58: 原盒 | D58: 原箱 | E58: 在售 | F58: 0 | I58: 简中 | J58: 未上架 | K58: 否 | M58: 2026-02-02T00:00:00 | O58: /products/onepiece-official/ebc-04-pack.png | Q58: 扩充包 | R58: 官方 onepiece-cardgame.cn 已发售（特别篇），本店未查到对应商品页，暂未上架。价格/库存/成本待你核实补录。 | U58: 海贼王
A59: EBC-03 ONE PIECE Heroines Edition 原盒（简中） | B59: EBC-03 | C59: 原盒 | D59: 原盒 | E59: 售罄 | F59: 0 | G59: 7500 | I59: 简中 | J59: 上架 | K59: 否 | M59: 2025-11-07T00:00:00 | Q59: 扩充包 | R59: 官方 onepiece-cardgame.cn 已发售（女角色主题特别篇），本店未查到对应商品页，暂未上架。价格/库存/成本待你核实补录。 | U59: 海贼王
A60: EBC-03 ONE PIECE Heroines Edition 散包（简中） | B60: EBC-03 | C60: 原盒 | D60: 散包 | E60: 在售 | F60: 0 | G60: 312 | I60: 简中 | J60: 未上架 | K60: 否 | M60: 2025-11-07T00:00:00 | Q60: 扩充包 | R60: 官方 onepiece-cardgame.cn 已发售（女角色主题特别篇），本店未查到对应商品页，暂未上架。价格/库存/成本待你核实补录。 | U60: 海贼王
A61: EBC-03 ONE PIECE Heroines Edition 原箱（简中） | B61: EBC-03 | C61: 原盒 | D61: 原箱 | E61: 在售 | F61: 0 | G61: 90000 | I61: 简中 | J61: 未上架 | K61: 否 | M61: 2025-11-07T00:00:00 | Q61: 扩充包 | R61: 官方 onepiece-cardgame.cn 已发售（女角色主题特别篇），本店未查到对应商品页，暂未上架。价格/库存/成本待你核实补录。 | U61: 海贼王
A62: EBC-02 Anime 25th Collection 原盒（简中） | B62: EBC-02 | C62: 原盒 | D62: 原盒 | E62: 售罄 | F62: 0 | G62: 7800 | I62: 简中 | J62: 上架 | K62: 否 | M62: 2025-03-12T00:00:00 | Q62: 扩充包 | R62: 官方 onepiece-cardgame.cn 已发售（动画25周年特别篇），本店未查到对应商品页，暂未上架。价格/库存/成本待你核实补录。 | U62: 海贼王
...

Sheet 火影
A1: 火影 · PIMART
A2: 【大纲 1 / 2】点「1」只显示原盒主行（日常改库存/售价）。点「2」或行号旁「+」展开散包/原箱（有规格的新品写到这一层）。新品：先写规格=原盒，再在下方挂散包、原箱两行。
Q3: ← 规格列：橙=原箱 | 蓝=原盒 | 绿=散包 | 紫=商品类型（日常改库存/销售价即可）
A4: 商品名 | B4: 系列 | C4: 盒型/类型 | D4: 规格 | E4: 销售状态 | F4: 库存 | G4: 销售价(JPY) | H4: 成本价(CNY) | I4: 语言 | J4: 网站状态 | K4: 是否预售 | L4: 首页推荐 | M4: 发售日 | N4: 发货天数 | O4: 图片 | P4: 优先级 | Q4: 原箱库存 | R4: 原箱销售价(JPY) | S4: 原箱建议售价(JPY) | T4: 原箱毛利(JPY) | U4: 原箱毛利率 | V4: 原箱库存金额(JPY) | W4: 原箱价格状态 | X4: 原箱库存状态 | Y4: 原箱调价建议 | Z4: 原盒库存 | AA4: 原盒销售价(JPY) | AB4: 原盒建议售价(JPY) | AC4: 原盒毛利(JPY) | AD4: 原盒毛利率 | AE4: 原盒库存金额(JPY) | AF4: 原盒价格状态 | AG4: 原盒库存状态 | AH4: 原盒调价建议 | AI4: 散包库存 | AJ4: 散包销售价(JPY) | AK4: 散包建议售价(JPY) | AL4: 散包毛利(JPY) | AM4: 散包毛利率 | AN4: 散包库存金额(JPY) | AO4: 散包价格状态 | AP4: 散包库存状态 | AQ4: 散包调价建议 | AR4: 备注 | AS4: 商品ID | AT4: SKU/Slug | AU4: 游戏 | AV4: 商品链接
A5: 单条：点「原盒」那一行【左边行号旁】的 + 展开散包/原箱，点 - 收回
A6: 卡游 / 官方
A8: 系列扩展
A10: 礼盒 / 周边
A12: 其他

Sheet 全量库存
A1: 全量库存 · 汇总
A2: 自动汇总各 IP 分页商品行（不含分组标题）。日常请在宝可梦/海贼王/火影页改库存与售价。
A4: 来源页 | B4: 商品名 | C4: 系列 | D4: 盒型/类型 | E4: 销售状态 | F4: 库存 | G4: 销售价(JPY) | H4: 备注
A5: 宝可梦 | B5: =宝可梦!A5 | C5: =宝可梦!B5 | D5: =宝可梦!C5 | E5: =宝可梦!D5 | F5: =宝可梦!E5 | G5: =宝可梦!G5 | H5: =宝可梦!#REF!
A6: 宝可梦 | B6: =宝可梦!A6 | C6: =宝可梦!B6 | D6: =宝可梦!C6 | E6: =宝可梦!D6 | F6: =宝可梦!E6 | G6: =宝可梦!G6 | H6: =宝可梦!#REF!
A7: 宝可梦 | B7: =宝可梦!A7 | C7: =宝可梦!B7 | D7: =宝可梦!C7 | E7: =宝可梦!D7 | F7: =宝可梦!E7 | G7: =宝可梦!G7 | H7: =宝可梦!#REF!
A8: 宝可梦 | B8: =宝可梦!A8 | C8: =宝可梦!B8 | D8: =宝可梦!C8 | E8: =宝可梦!D8 | F8: =宝可梦!E8 | G8: =宝可梦!G8 | H8: =宝可梦!#REF!
A9: 宝可梦 | B9: =宝可梦!A11 | C9: =宝可梦!B11 | D9: =宝可梦!C11 | E9: =宝可梦!D11 | F9: =宝可梦!E11 | G9: =宝可梦!G11 | H9: =宝可梦!#REF!
A10: 宝可梦 | B10: =宝可梦!A12 | C10: =宝可梦!B12 | D10: =宝可梦!C12 | E10: =宝可梦!D12 | F10: =宝可梦!E12 | G10: =宝可梦!G12 | H10: =宝可梦!#REF!
A11: 宝可梦 | B11: =宝可梦!A13 | C11: =宝可梦!B13 | D11: =宝可梦!C13 | E11: =宝可梦!D13 | F11: =宝可梦!E13 | G11: =宝可梦!G13 | H11: =宝可梦!#REF!
A12: 宝可梦 | B12: =宝可梦!A14 | C12: =宝可梦!B14 | D12: =宝可梦!C14 | E12: =宝可梦!D14 | F12: =宝可梦!E14 | G12: =宝可梦!G14 | H12: =宝可梦!#REF!
A13: 宝可梦 | B13: =宝可梦!A19 | C13: =宝可梦!B19 | D13: =宝可梦!C19 | E13: =宝可梦!D19 | F13: =宝可梦!E19 | G13: =宝可梦!G19 | H13: =宝可梦!#REF!
A14: 宝可梦 | B14: =宝可梦!A20 | C14: =宝可梦!B20 | D14: =宝可梦!C20 | E14: =宝可梦!D20 | F14: =宝可梦!E20 | G14: =宝可梦!G20 | H14: =宝可梦!#REF!
A15: 宝可梦 | B15: =宝可梦!A21 | C15: =宝可梦!B21 | D15: =宝可梦!C21 | E15: =宝可梦!D21 | F15: =宝可梦!E21 | G15: =宝可梦!G21 | H15: =宝可梦!#REF!
A16: 宝可梦 | B16: =宝可梦!A24 | C16: =宝可梦!B24 | D16: =宝可梦!C24 | E16: =宝可梦!D24 | F16: =宝可梦!E24 | G16: =宝可梦!G24 | H16: =宝可梦!#REF!
A17: 宝可梦 | B17: =宝可梦!A25 | C17: =宝可梦!B25 | D17: =宝可梦!C25 | E17: =宝可梦!D25 | F17: =宝可梦!E25 | G17: =宝可梦!G25 | H17: =宝可梦!#REF!
A18: 宝可梦 | B18: =宝可梦!A26 | C18: =宝可梦!B26 | D18: =宝可梦!C26 | E18: =宝可梦!D26 | F18: =宝可梦!E26 | G18: =宝可梦!G26 | H18: =宝可梦!#REF!
A19: 宝可梦 | B19: =宝可梦!A29 | C19: =宝可梦!B29 | D19: =宝可梦!C29 | E19: =宝可梦!D29 | F19: =宝可梦!E29 | G19: =宝可梦!G29 | H19: =宝可梦!#REF!
A20: 宝可梦 | B20: =宝可梦!A30 | C20: =宝可梦!B30 | D20: =宝可梦!C30 | E20: =宝可梦!D30 | F20: =宝可梦!E30 | G20: =宝可梦!G30 | H20: =宝可梦!#REF!
A21: 宝可梦 | B21: =宝可梦!A31 | C21: =宝可梦!B31 | D21: =宝可梦!C31 | E21: =宝可梦!D31 | F21: =宝可梦!E31 | G21: =宝可梦!G31 | H21: =宝可梦!#REF!
A22: 宝可梦 | B22: =宝可梦!A34 | C22: =宝可梦!B34 | D22: =宝可梦!C34 | E22: =宝可梦!D34 | F22: =宝可梦!E34 | G22: =宝可梦!G34 | H22: =宝可梦!#REF!
A23: 宝可梦 | B23: =宝可梦!A35 | C23: =宝可梦!B35 | D23: =宝可梦!C35 | E23: =宝可梦!D35 | F23: =宝可梦!E35 | G23: =宝可梦!G35 | H23: =宝可梦!#REF!
A24: 宝可梦 | B24: =宝可梦!A36 | C24: =宝可梦!B36 | D24: =宝可梦!C36 | E24: =宝可梦!D36 | F24: =宝可梦!E36 | G24: =宝可梦!G36 | H24: =宝可梦!#REF!
A25: 宝可梦 | B25: =宝可梦!A39 | C25: =宝可梦!B39 | D25: =宝可梦!C39 | E25: =宝可梦!D39 | F25: =宝可梦!E39 | G25: =宝可梦!G39 | H25: =宝可梦!#REF!
A26: 宝可梦 | B26: =宝可梦!A40 | C26: =宝可梦!B40 | D26: =宝可梦!C40 | E26: =宝可梦!D40 | F26: =宝可梦!E40 | G26: =宝可梦!G40 | H26: =宝可梦!#REF!
A27: 宝可梦 | B27: =宝可梦!A41 | C27: =宝可梦!B41 | D27: =宝可梦!C41 | E27: =宝可梦!D41 | F27: =宝可梦!E41 | G27: =宝可梦!G41 | H27: =宝可梦!#REF!
A28: 宝可梦 | B28: =宝可梦!A44 | C28: =宝可梦!B44 | D28: =宝可梦!C44 | E28: =宝可梦!D44 | F28: =宝可梦!E44 | G28: =宝可梦!G44 | H28: =宝可梦!#REF!
A29: 宝可梦 | B29: =宝可梦!A45 | C29: =宝可梦!B45 | D29: =宝可梦!C45 | E29: =宝可梦!D45 | F29: =宝可梦!E45 | G29: =宝可梦!G45 | H29: =宝可梦!#REF!
A30: 宝可梦 | B30: =宝可梦!A50 | C30: =宝可梦!B50 | D30: =宝可梦!C50 | E30: =宝可梦!D50 | F30: =宝可梦!E50 | G30: =宝可梦!G50 | H30: =宝可梦!#REF!
A31: 宝可梦 | B31: =宝可梦!A51 | C31: =宝可梦!B51 | D31: =宝可梦!C51 | E31: =宝可梦!D51 | F31: =宝可梦!E51 | G31: =宝可梦!G51 | H31: =宝可梦!#REF!
A32: 宝可梦 | B32: =宝可梦!A54 | C32: =宝可梦!B54 | D32: =宝可梦!C54 | E32: =宝可梦!D54 | F32: =宝可梦!E54 | G32: =宝可梦!G54 | H32: =宝可梦!#REF!
A33: 宝可梦 | B33: =宝可梦!A55 | C33: =宝可梦!B55 | D33: =宝可梦!C55 | E33: =宝可梦!D55 | F33: =宝可梦!E55 | G33: =宝可梦!G55 | H33: =宝可梦!#REF!
A34: 宝可梦 | B34: =宝可梦!A58 | C34: =宝可梦!B58 | D34: =宝可梦!C58 | E34: =宝可梦!D58 | F34: =宝可梦!E58 | G34: =宝可梦!G58 | H34: =宝可梦!#REF!
A35: 宝可梦 | B35: =宝可梦!A59 | C35: =宝可梦!B59 | D35: =宝可梦!C59 | E35: =宝可梦!D59 | F35: =宝可梦!E59 | G35: =宝可梦!G59 | H35: =宝可梦!#REF!
A36: 宝可梦 | B36: =宝可梦!A62 | C36: =宝可梦!B62 | D36: =宝可梦!C62 | E36: =宝可梦!D62 | F36: =宝可梦!E62 | G36: =宝可梦!G62 | H36: =宝可梦!#REF!
A37: 宝可梦 | B37: =宝可梦!A63 | C37: =宝可梦!B63 | D37: =宝可梦!C63 | E37: =宝可梦!D63 | F37: =宝可梦!E63 | G37: =宝可梦!G63 | H37: =宝可梦!#REF!
A38: 宝可梦 | B38: =宝可梦!A66 | C38: =宝可梦!B66 | D38: =宝可梦!C66 | E38: =宝可梦!D66 | F38: =宝可梦!E66 | G38: =宝可梦!G66 | H38: =宝可梦!#REF!
A39: 宝可梦 | B39: =宝可梦!A67 | C39: =宝可梦!B67 | D39: =宝可梦!C67 | E39: =宝可梦!D67 | F39: =宝可梦!E67 | G39: =宝可梦!G67 | H39: =宝可梦!#REF!
A40: 宝可梦 | B40: =宝可梦!A70 | C40: =宝可梦!B70 | D40: =宝可梦!C70 | E40: =宝可梦!D70 | F40: =宝可梦!E70 | G40: =宝可梦!G70 | H40: =宝可梦!#REF!
A41: 宝可梦 | B41: =宝可梦!A71 | C41: =宝可梦!B71 | D41: =宝可梦!C71 | E41: =宝可梦!D71 | F41: =宝可梦!E71 | G41: =宝可梦!G71 | H41: =宝可梦!#REF!
...

Sheet 售罄与未上架
A1: 销售状态 | B1: 商品名 | C1: 系列 | D1: 盒型 | E1: 网站状态 | F1: 库存 | G1: 销售价(JPY) | H1: Obsidian状态 | I1: 来源 | J1: 备注
A2: 售罄 | B2: 宝石包第二弹 BOX（简中） | C2: 宝石包 | D2: 宝石包 | E2: 上架 | F2: 0 | G2: 8500 | I2: 网站公开商品页 + Obsidian | J2: 简中宝可梦 宝石包 第二弹（CBB2C）原盒，2025年5月16日发售，每盒15包，每包4张全闪。
A3: 售罄 | B3: 宝石包第三弹 BOX（简中） | C3: 宝石包 | D3: 宝石包 | E3: 上架 | F3: 0 | G3: 8000 | I3: 网站公开商品页 + Obsidian | J3: 简中宝可梦 宝石包 第三弹（CBB3C）原盒，2025年9月26日发售，每盒15包，每包4张全闪。
A4: 售罄 | B4: 宝石包第四弹 BOX（简中） | C4: 宝石包 | D4: 宝石包 | E4: 上架 | F4: 0 | G4: 7600 | I4: 网站公开商品页 + Obsidian | J4: 简中宝可梦 宝石包 第四弹（CBB4C）原盒，2026年2月6日发售，每盒15包，每包4张全闪。
A5: 售罄 | B5: 宝石包第一弹 BOX（简中） | C5: 宝石包 | D5: 宝石包 | E5: 上架 | F5: 0 | G5: 9000 | I5: 网站公开商品页 + Obsidian | J5: 简中宝可梦 宝石包 第一弹（CBB1C）原盒，2025年1月17日发售，每盒15包，每包4张全闪。
A6: 售罄 | B6: 极巨攻防 BOX（简中） | C6: 剑&盾 CS1.5 | D6: 瘦盒 | E6: 上架 | F6: 0 | G6: 3800 | I6: 网站公开商品页 + Obsidian | J6: 简中宝可梦 剑&盾 强化包 极巨攻防（CS1.5C），6张/包×20包/盒。
A7: 售罄 | B7: 极巨争锋 雷 BOX（简中） | C7: 剑&盾 CS1a | D7: 肥盒 | E7: 上架 | F7: 0 | G7: 4800 | I7: 网站公开商品页 + Obsidian | J7: 简中宝可梦 剑&盾 极巨争锋 雷（CS1aC），2023年5月19日发售，5张/包×30包/盒。
A8: 售罄 | B8: 极巨争锋 焰 BOX（简中） | C8: 剑&盾 CS1b | D8: 肥盒 | E8: 上架 | F8: 0 | G8: 4800 | I8: 网站公开商品页 + Obsidian | J8: 简中宝可梦 剑&盾 极巨争锋 焰（CS1bC），2023年5月19日发售，5张/包×30包/盒。
A9: 售罄 | B9: 璀璨反击 BOX（简中） | C9: 剑&盾 CS2.5 | D9: 瘦盒 | E9: 上架 | F9: 0 | G9: 3800 | I9: 网站公开商品页 + Obsidian | J9: 简中宝可梦 剑&盾 强化包 璀璨反击（CS2.5C），6张/包×20包/盒。
A10: 售罄 | B10: 浓墨重彩 黎 BOX（简中） | C10: 剑&盾 CS2a | D10: 肥盒 | E10: 上架 | F10: 0 | G10: 4800 | I10: 网站公开商品页 + Obsidian | J10: 简中宝可梦 剑&盾 浓墨重彩 黎（CS2aC），2023年8月18日发售，5张/包×30包/盒。
A11: 售罄 | B11: 浓墨重彩 靛 BOX（简中） | C11: 剑&盾 CS2b | D11: 肥盒 | E11: 上架 | F11: 0 | G11: 4800 | I11: 网站公开商品页 + Obsidian | J11: 简中宝可梦 剑&盾 浓墨重彩 靛（CS2bC），2023年8月18日发售，5张/包×30包/盒。
A12: 售罄 | B12: 怒炎灼天 BOX（简中） | C12: 剑&盾 CS3.5 | D12: 瘦盒 | E12: 上架 | F12: 0 | G12: 3800 | I12: 网站公开商品页 + Obsidian | J12: 简中宝可梦 剑&盾 强化包 怒炎灼天（CS3.5C），6张/包×20包/盒。
A13: 售罄 | B13: 洪荒演武 茂 BOX（简中） | C13: 剑&盾 CS3a | D13: 肥盒 | E13: 上架 | F13: 0 | G13: 5000 | I13: 网站公开商品页 + Obsidian | J13: 简中宝可梦 剑&盾 洪荒演武 茂（CS3aC），2023年11月17日发售，5张/包×30包/盒。
... A35: 售罄 | B35: 璀璨诡幻 BOX（简中） | C35: 朱・紫 CSV8c | D35: 肥盒 | E35: 上架 | F35: 0 | G35: 6000 | I35: 网站公开商品页 + Obsidian | J35: 简中宝可梦 朱&紫 璀璨诡幻（CSV8C）原盒，2026年3月13日发售，每盒30包，每包5张。
A36: 未上架 | B36: 朱紫 三连击 | C36: 宝可梦卡牌 | D36: booster_box | E36: 草稿 | F36: 0 | H36: draft | I36: Obsidian 产品笔记 | J36: 未在网站公开 Pokemon 列表中命中：C:\Users\33092\Desktop\obsi\KANDA\KKCARD OS\Products\JP\SV1A-トリプレットビート.md

Sheet 图片库
A1: 总表行号 | B1: 商品名 | C1: 系列/编号 | D1: 匹配状态 | E1: pokemon.cn标题 | F1: 本地文件名 | G1: 图片相对路径(网站) | H1: 来源URL | I1: 备注
A2: 6 | B2: 补充包 共逐荣光 瘦盒 BOX（简中） | C2: 朱・紫 CSV10c | D2: 已备份 | E2: 补充包 共逐荣光 瘦盒 BOX（简中） | F2: csv10c-slim.png | G2: /products/csv10c-slim.png | I2: DB status=上架
A3: 9 | B3: 补充包 共逐荣光 肥盒 BOX（简中） | C3: 朱・紫 CSV10c | D3: 已备份 | E3: 补充包 共逐荣光 肥盒 BOX（简中） | F3: csv10c-fat.png | G3: /products/csv10c-fat.png | I3: DB status=上架
A4: 13 | B4: 补充包 星彩晶璃 瘦盒 BOX（简中） | C4: 朱・紫 CSV9c | D4: 已备份 | E4: 补充包 星彩晶璃 瘦盒 BOX（简中） | F4: csv9c-slim.png | G4: /products/csv9c-slim.png | I4: DB status=上架
A5: 16 | B5: 补充包 星彩晶璃 肥盒 BOX（简中） | C5: 朱・紫 CSV9c | D5: 已备份 | E5: 补充包 星彩晶璃 肥盒 BOX（简中） | F5: csv9c-fat.png | G5: /products/csv9c-fat.png | I5: DB status=上架
A6: 20 | B6: 补充包 璀璨诡幻 瘦盒 BOX（简中） | C6: 朱・紫 CSV8c | D6: 已备份 | E6: 补充包 璀璨诡幻 瘦盒 BOX（简中） | F6: csv8c-slim.png | G6: /products/csv8c-slim.png | I6: DB status=上架
A7: 23 | B7: 补充包 璀璨诡幻 肥盒 BOX（简中） | C7: 朱・紫 CSV8c | D7: 已备份 | E7: 补充包 璀璨诡幻 肥盒 BOX（简中） | F7: csv8c-fat.png | G7: /products/csv8c-fat.png | I7: DB status=上架
A8: 27 | B8: 补充包 利刃猛醒 瘦盒 BOX（简中） | C8: 朱・紫 CSV7c | D8: 已备份 | E8: 补充包 利刃猛醒 瘦盒 BOX（简中） | F8: csv7c-slim.png | G8: /products/csv7c-slim.png | I8: DB status=上架
A9: 30 | B9: 补充包 利刃猛醒 肥盒 BOX（简中） | C9: 朱・紫 CSV7c | D9: 已备份 | E9: 补充包 利刃猛醒 肥盒 BOX（简中） | F9: csv7c-fat.png | G9: /products/csv7c-fat.png | I9: DB status=上架
A10: 34 | B10: 补充包 真实玄虚 瘦盒 BOX（简中） | C10: 朱・紫 CSV6c | D10: 已备份 | E10: 补充包 真实玄虚 瘦盒 BOX（简中） | F10: csv6c-slim.png | G10: /products/csv6c-slim.png | I10: DB status=上架
A11: 37 | B11: 补充包 真实玄虚 肥盒 BOX（简中） | C11: 朱・紫 CSV6c | D11: 已备份 | E11: 补充包 真实玄虚 肥盒 BOX（简中） | F11: csv6c-fat.png | G11: /products/csv6c-fat.png | I11: DB status=上架
A12: 41 | B12: 补充包 黑晶炽诚 瘦盒 BOX（简中） | C12: 朱・紫 CSV5c | D12: 已备份 | E12: 补充包 黑晶炽诚 瘦盒 BOX（简中） | F12: csv5c-slim.png | G12: /products/csv5c-slim.png | I12: DB status=上架
A13: 44 | B13: 补充包 黑晶炽诚 肥盒 BOX（简中） | C13: 朱・紫 CSV5c | D13: 已备份 | E13: 补充包 黑晶炽诚 肥盒 BOX（简中） | F13: csv5c-fat.png | G13: /products/csv5c-fat.png | I13: DB status=上架
... A152: 53 | B152: OPC-01 冒险的黎明 原箱（简中） | C152: OPC-01 | D152: 已备份 | E152: OPC-01 冒险的黎明 原箱（简中） | F152: opc-01-pack.png | G152: /products/onepiece-official/opc-01-pack.png | I152: DB status=上架
A153: 55 | B153: EB 特别补充包 | D153: 已备份 | E153: EB 特别补充包 | F153: placeholder.svg | G153: /products/placeholder.svg | I153: DB status=下架
A154: 56 | B154: EBC-04 艾格赫德危机 原盒（简中） | C154: EBC-04 | D154: 已备份 | E154: EBC-04 艾格赫德危机 原盒（简中） | F154: ebc-04-pack.png | G154: /products/onepiece-official/ebc-04-pack.png | I154: DB status=上架
A155: 57 | B155: EBC-04 艾格赫德危机 散包（简中） | C155: EBC-04 | D155: 已备份 | E155: EBC-04 艾格赫德危机 散包（简中） | F155: ebc-04-pack.png | G155: /products/onepiece-official/ebc-04-pack.png | I155: DB status=上架
A156: 58 | B156: EBC-04 艾格赫德危机 原箱（简中） | C156: EBC-04 | D156: 已备份 | E156: EBC-04 艾格赫德危机 原箱（简中） | F156: ebc-04-pack.png | G156: /products/onepiece-official/ebc-04-pack.png | I156: DB status=上架
A157: 65 | B157: EB-01 特别补充包 纪念收藏合集 原盒（简中） | C157: EB-01 | D157: 已备份 | E157: EB-01 特别补充包 纪念收藏合集 原盒（简中） | F157: ebc-01-pack.png | G157: /products/onepiece-official/ebc-01-pack.png | I157: DB status=上架
A158: 66 | B158: PRB 豪华补充包 / 典藏包 | D158: 已备份 | E158: PRB 豪华补充包 / 典藏包 | F158: placeholder.svg | G158: /products/placeholder.svg | I158: DB status=下架
A159: 67 | B159: PRBC-02 历代典藏合集 Vol.2 原盒（简中） | C159: PRBC-02 | D159: 已备份 | E159: PRBC-02 历代典藏合集 Vol.2 原盒（简中） | F159: prbc-02-pack.png | G159: /products/onepiece-official/prbc-02-pack.png | I159: DB status=上架
A160: 68 | B160: PRBC-02 历代典藏合集 Vol.2 散包（简中） | C160: PRBC-02 | D160: 已备份 | E160: PRBC-02 历代典藏合集 Vol.2 散包（简中） | F160: prbc-02-pack.png | G160: /products/onepiece-official/prbc-02-pack.png | I160: DB status=上架
A161: 69 | B161: PRBC-02 历代典藏合集 Vol.2 原箱（简中） | C161: PRBC-02 | D161: 已备份 | E161: PRBC-02 历代典藏合集 Vol.2 原箱（简中） | F161: prbc-02-pack.png | G161: /products/onepiece-official/prbc-02-pack.png | I161: DB status=上架
A162: 70 | B162: PRBC-01 历代典藏合集 原盒（简中） | C162: PRBC-01 | D162: 已备份 | E162: PRBC-01 历代典藏合集 原盒（简中） | F162: prbc-01-pack.png | G162: /products/onepiece-official/prbc-01-pack.png | I162: DB status=上架
A163: 71 | B163: PRBC-01 历代典藏合集 散包（简中） | C163: PRBC-01 | D163: 已备份 | E163: PRBC-01 历代典藏合集 散包（简中） | F163: prbc-01-pack.png | G163: /products/onepiece-official/prbc-01-pack.png | I163: DB status=上架
A164: 72 | B164: PRBC-01 历代典藏合集 原箱（简中） | C164: PRBC-01 | D164: 已备份 | E164: PRBC-01 历代典藏合集 原箱（简中） | F164: prbc-01-pack.png | G164: /products/onepiece-official/prbc-01-pack.png | I164: DB status=上架
A165: 75 | B165: 基本卡组 对战进阶套组2026（官方名称，简中定价待官方公布） | C165: STC-31~36 | D165: 已备份 | E165: 基本卡组 对战进阶套组2026（官方名称，简中定价待官方公布） | F165: stc-31-36-decks.png | G165: /products/onepiece-official/stc-31-36-decks.png | I165: DB status=上架
A166: 76 | B166: 基本卡组 艾格赫德（官方名称，简中定价待官方公布） | C166: STC-29 | D166: 已备份 | E166: 基本卡组 艾格赫德（官方名称，简中定价待官方公布） | F166: stc-29-deck.png | G166: /products/onepiece-official/stc-29-deck.png | I166: DB status=上架
A167: 77 | B167: 基本卡组 对战进阶套组2025（官方名称，简中定价待官方公布） | C167: STC-23~28 | D167: 已备份 | E167: 基本卡组 对战进阶套组2025（官方名称，简中定价待官方公布） | F167: stc-23-28-decks.png | G167: /products/onepiece-official/stc-23-28-decks.png | I167: DB status=上架
A168: 78 | B168: 基本卡组 两年后再出发（官方名称，简中定价待官方公布） | C168: STC-14 | D168: 已备份 | E168: 基本卡组 两年后再出发（官方名称，简中定价待官方公布） | F168: stc-14-deck.png | G168: /products/onepiece-official/stc-14-deck.png | I168: DB status=上架
A169: 79 | B169: 究极进阶卡组 奇迹的再会（官方名称，简中定价待官方公布） | C169: STC-13 | D169: 已备份 | E169: 究极进阶卡组 奇迹的再会（官方名称，简中定价待官方公布） | F169: stc-13-deck.png | G169: /products/onepiece-official/stc-13-deck.png | I169: DB status=上架
A170: 80 | B170: 基本卡组 佐罗＆山智（官方名称，简中定价待官方公布） | C170: STC-12 | D170: 已备份 | E170: 基本卡组 佐罗＆山智（官方名称，简中定价待官方公布） | F170: stc-12-deck.png | G170: /products/onepiece-official/stc-12-deck.png | I170: DB status=上架
... A198: 110 | B198: 航海王卡牌对战 对战桌垫+卡牌盒套装 -25周年版- （简中） | C198: 航海王礼盒 | D198: 已备份 | E198: 航海王卡牌对战 对战桌垫+卡牌盒套装 -25周年版- （简中） | F198: gift-26.jpg | G198: /products/onepiece-official/gift-26.jpg | I198: DB status=上架

Sheet 出入库记录
A1: 日期 | B1: SKU/Slug | C1: 商品名 | D1: 操作类型 | E1: 数量 | F1: 单价(JPY) | G1: 金额(JPY) | H1: 平台/渠道 | I1: 订单/单号 | J1: 备注
